<?xml version="1.0"?>
<robot name="kimm_wheel_legged_robot">
  <material name="silver">
    <color rgba="0.700 0.700 0.700 1.000"/>
  </material>

  <link name="base_link"> </link>
  <joint name="base_link_to_pelvis" type="fixed">
    <parent link="base_link"/>
    <child  link="pelvis"/>
    <origin rpy="1.5708 0 -1.5708" xyz="0 0 0"/>
  </joint>

  <!-- Links -->
  <link name="pelvis">
    <inertial>
      <origin xyz="2.1438791285322582e-08 0.04053540705238699 -0.0010758453861736091" rpy="0 0 0"/>
      <mass value="3.813"/>
      <inertia ixx="0.002220" iyy="0.000752" izz="0.001699" ixy="0" ixz="0" iyz="0"/>
    </inertial>
    <visual>
      <origin rpy="0 0 0" xyz="0 0 0"/>
      <geometry>
        <mesh filename="package://kimm_wheel_legged_robot_description/meshes/pelvis.stl" scale="0.001 0.001 0.001"/>
      </geometry>
      <material name="silver"/>
    </visual>
    <collision>
      <origin rpy="0 0 0" xyz="0 0 0"/>
      <geometry>
        <mesh filename="package://kimm_wheel_legged_robot_description/meshes/pelvis.stl" scale="0.001 0.001 0.001"/>
      </geometry>
    </collision>
  </link>
  <link name="torso_link">
    <inertial>
      <origin xyz="0 0.4 0.05" rpy="0 0 0"/>
      <mass value="15.0"/>
      <inertia ixx="0.656" iyy="0.088" izz="0.156" ixy="0.0" ixz="0.0" iyz="0.113"/>
    </inertial>
    <visual>
      <origin rpy="0 0 0" xyz="0.0 -0.0862 -0.0"/>
      <geometry>
        <mesh filename="package://kimm_wheel_legged_robot_description/meshes/torso_link.stl" scale="0.001 0.001 0.001"/>
      </geometry>
      <material name="silver"/>
    </visual>
    <collision>
      <origin rpy="0 0 0" xyz="0.0 -0.0862 -0.0"/>
      <geometry>
        <mesh filename="package://kimm_wheel_legged_robot_description/meshes/torso_link.stl" scale="0.001 0.001 0.001"/>
      </geometry>
    </collision>
  </link>
  <link name="left_hip_roll_link">
    <inertial>
      <origin xyz="-0.03032913107746091 2.474453244607486e-05 -0.0001940144294897979" rpy="0 0 0"/>
      <mass value="1.0"/>
      <inertia ixx="0.001365" iyy="0.001066" izz="0.001076" ixy="0" ixz="0" iyz="0"/>
    </inertial>
    <visual>
      <origin rpy="0 0 0" xyz="0.0093 -0.0 0.0"/>
      <geometry>
        <mesh filename="package://kimm_wheel_legged_robot_description/meshes/left_hip_roll_link.stl" scale="0.001 0.001 0.001"/>
      </geometry>
      <material name="silver"/>
    </visual>
    <collision>
      <origin rpy="0 0 0" xyz="0.0093 -0.0 0.0"/>
      <geometry>
        <mesh filename="package://kimm_wheel_legged_robot_description/meshes/left_hip_roll_link.stl" scale="0.001 0.001 0.001"/>
      </geometry>
    </collision>
  </link>
  <link name="right_hip_roll_link">
    <inertial>
      <origin xyz="0.03032913107746091 2.474453244607486e-05 -0.0001940144294897979" rpy="0 0 0"/>
      <mass value="1.0"/>
      <inertia ixx="0.001365" iyy="0.001066" izz="0.001076" ixy="0" ixz="0" iyz="0"/>
    </inertial>
    <visual>
      <origin rpy="0 0 0" xyz="-0.0093 0.0 -0.0"/>
      <geometry>
        <mesh filename="package://kimm_wheel_legged_robot_description/meshes/right_hip_roll_link.stl" scale="0.001 0.001 0.001"/>
      </geometry>
      <material name="silver"/>
    </visual>
    <collision>
      <origin rpy="0 0 0" xyz="-0.0093 0.0 -0.0"/>
      <geometry>
        <mesh filename="package://kimm_wheel_legged_robot_description/meshes/right_hip_roll_link.stl" scale="0.001 0.001 0.001"/>
      </geometry>
    </collision>
  </link>
  <link name="left_hip_yaw_link">
    <inertial>
      <origin xyz="-0.07390170630152854 9.962373480358716e-05 -0.002378445294013718" rpy="0 0 0"/>
      <mass value="1.0"/>
      <inertia ixx="0.001059" iyy="0.001367" izz="0.001395" ixy="0" ixz="0" iyz="0"/>
    </inertial>
    <visual>
      <origin rpy="0 0 0" xyz="0.06325 0.0 0.0"/>
      <geometry>
        <mesh filename="package://kimm_wheel_legged_robot_description/meshes/left_hip_yaw_link.stl" scale="0.001 0.001 0.001"/>
      </geometry>
      <material name="silver"/>
    </visual>
    <collision>
      <origin rpy="0 0 0" xyz="0.06325 0.0 0.0"/>
      <geometry>
        <mesh filename="package://kimm_wheel_legged_robot_description/meshes/left_hip_yaw_link.stl" scale="0.001 0.001 0.001"/>
      </geometry>
    </collision>
  </link>
  <link name="right_hip_yaw_link">
    <inertial>
      <origin xyz="0.07390170646682584 9.962377136097075e-05 -0.0023784453818592064" rpy="0 0 0"/>
      <mass value="1.0"/>
      <inertia ixx="0.001059" iyy="0.001367" izz="0.001395" ixy="0" ixz="0" iyz="0"/>
    </inertial>
    <visual>
      <origin rpy="0 0 0" xyz="-0.06325 0.0 0.0"/>
      <geometry>
        <mesh filename="package://kimm_wheel_legged_robot_description/meshes/right_hip_yaw_link.stl" scale="0.001 0.001 0.001"/>
      </geometry>
      <material name="silver"/>
    </visual>
    <collision>
      <origin rpy="0 0 0" xyz="-0.06325 0.0 0.0"/>
      <geometry>
        <mesh filename="package://kimm_wheel_legged_robot_description/meshes/right_hip_yaw_link.stl" scale="0.001 0.001 0.001"/>
      </geometry>
    </collision>
  </link>
  <link name="left_hip_pitch_link">
    <inertial>
      <origin xyz="-8.045084226449006e-05 -0.08157488033480476 0.03975673852831995" rpy="0 0 0"/>
      <mass value="1.0"/>
      <inertia ixx="0.001916" iyy="0.001291" izz="0.001703" ixy="0" ixz="0" iyz="0"/>
    </inertial>
    <visual>
      <origin rpy="0 0 0" xyz="0.1424 0.0 0.03875"/>
      <geometry>
        <mesh filename="package://kimm_wheel_legged_robot_description/meshes/left_hip_pitch_link.stl" scale="0.001 0.001 0.001"/>
      </geometry>
      <material name="silver"/>
    </visual>
    <collision>
      <origin rpy="0 0 0" xyz="0.1424 0.0 0.03875"/>
      <geometry>
        <mesh filename="package://kimm_wheel_legged_robot_description/meshes/left_hip_pitch_link.stl" scale="0.001 0.001 0.001"/>
      </geometry>
    </collision>
  </link>
  <link name="right_hip_pitch_link">
    <inertial>
      <origin xyz="8.045084226449006e-05 -0.08157488033480476 0.03975673852831995" rpy="0 0 0"/>
      <mass value="1.0"/>
      <inertia ixx="0.001916" iyy="0.001291" izz="0.001703" ixy="0" ixz="0" iyz="0"/>
    </inertial>
    <visual>
      <origin rpy="0 0 0" xyz="-0.1424 0.0 0.03875"/>
      <geometry>
        <mesh filename="package://kimm_wheel_legged_robot_description/meshes/right_hip_pitch_link.stl" scale="0.001 0.001 0.001"/>
      </geometry>
      <material name="silver"/>
    </visual>
    <collision>
      <origin rpy="0 0 0" xyz="-0.1424 0.0 0.03875"/>
      <geometry>
        <mesh filename="package://kimm_wheel_legged_robot_description/meshes/right_hip_pitch_link.stl" scale="0.001 0.001 0.001"/>
      </geometry>
    </collision>
  </link>
  <link name="left_thigh_wheel_link">
    <inertial>
      <origin xyz="-0.014340044848925454 -0.1505203928999803 0.0003972335107866499" rpy="0 0 0"/>
      <mass value="2.0"/>
      <inertia ixx="0.012183" iyy="0.003498" izz="0.013487" ixy="0" ixz="0" iyz="0"/>
    </inertial>
    <visual>
      <origin rpy="0 0 0" xyz="0.1424 0.11825 -0.0001"/>
      <geometry>
        <mesh filename="package://kimm_wheel_legged_robot_description/meshes/left_thigh_wheel_link.stl" scale="0.001 0.001 0.001"/>
      </geometry>
      <material name="silver"/>
    </visual>
    <collision>
      <origin rpy="0 0 0" xyz="0.1424 0.11825 -0.0001"/>
      <geometry>
        <mesh filename="package://kimm_wheel_legged_robot_description/meshes/left_thigh_wheel_link.stl" scale="0.001 0.001 0.001"/>
      </geometry>
    </collision>
  </link>
  <link name="right_thigh_wheel_link">
    <inertial>
      <origin xyz="0.014340044848925454 -0.1505203928999803 0.0003972335107866499" rpy="0 0 0"/>
      <mass value="2.0"/>
      <inertia ixx="0.012183" iyy="0.003498" izz="0.013487" ixy="0" ixz="0" iyz="0"/>
    </inertial>
    <visual>
      <origin rpy="0 0 0" xyz="-0.1424 0.11825 -0.0001"/>
      <geometry>
        <mesh filename="package://kimm_wheel_legged_robot_description/meshes/right_thigh_wheel_link.stl" scale="0.001 0.001 0.001"/>
      </geometry>
      <material name="silver"/>
    </visual>
    <collision>
      <origin rpy="0 0 0" xyz="-0.1424 0.11825 -0.0001"/>
      <geometry>
        <mesh filename="package://kimm_wheel_legged_robot_description/meshes/right_thigh_wheel_link.stl" scale="0.001 0.001 0.001"/>
      </geometry>
    </collision>
  </link>
  <link name="right_wheel">
    <inertial>
      <origin xyz="0.06356997620942698 -5.012545836596827e-05 -5.327760995034731e-05" rpy="0 0 0"/>
      <mass value="1.2"/>
      <inertia ixx="0.010303" iyy="0.005390" izz="0.005390" ixy="0" ixz="0" iyz="0"/>
    </inertial>
    <visual>
      <origin rpy="0 0 0" xyz="-0.2059 0.3499 -0.0001"/>
      <geometry>
        <mesh filename="package://kimm_wheel_legged_robot_description/meshes/right_wheel.stl" scale="0.001 0.001 0.001"/>
      </geometry>
      <material name="silver"/>
    </visual>
    <collision>
      <origin rpy="0 0 0" xyz="-0.2059 0.3499 -0.0001"/>
      <geometry>
        <mesh filename="package://kimm_wheel_legged_robot_description/meshes/right_wheel.stl" scale="0.001 0.001 0.001"/>
      </geometry>
      <surface>
        <friction>
          <ode>
            <mu>2.0</mu>       
            <mu2>0.8</mu2>      
            <slip1>0.0</slip1>  
            <slip2>0.01</slip2> 
          </ode>
          <fdir1>1 0 0</fdir1>  
        </friction>
        <contact>
          <ode>
            <kp>1000000</kp>
            <kd>1000</kd>
            <max_vel>0.2</max_vel>
            <min_depth>0.001</min_depth>
          </ode>
        </contact>
      </surface>
    </collision>
  </link>
  <link name="left_wheel">
    <inertial>
      <origin xyz="-0.06356997620942698 -5.012545836596827e-05 -5.327760995034731e-05" rpy="0 0 0"/>
      <mass value="1.2"/>
      <inertia ixx="0.010303" iyy="0.005390" izz="0.005390" ixy="0" ixz="0" iyz="0"/>
    </inertial>
    <visual>
      <origin rpy="0 0 0" xyz="0.2059 0.3499 -0.0001"/>
      <geometry>
        <mesh filename="package://kimm_wheel_legged_robot_description/meshes/left_wheel.stl" scale="0.001 0.001 0.001"/>
      </geometry>
      <material name="silver"/>
    </visual>
    <collision>
      <origin rpy="0 0 0" xyz="0.2059 0.3499 -0.0001"/>
      <geometry>
        <mesh filename="package://kimm_wheel_legged_robot_description/meshes/left_wheel.stl" scale="0.001 0.001 0.001"/>
      </geometry>
      <surface>
        <friction>
          <ode>
            <mu>2.0</mu>        
            <mu2>0.8</mu2>      
            <slip1>0.0</slip1> 
            <slip2>0.01</slip2> 
          </ode>
          <fdir1>1 0 0</fdir1>  
        </friction>
        <contact>
          <ode>
            <kp>1000000</kp>
            <kd>1000</kd>
            <max_vel>0.2</max_vel>
            <min_depth>0.001</min_depth>
          </ode>
        </contact>
      </surface>
    </collision>
  </link>
  <link name="left_knee_link">
    <inertial>
      <origin xyz="0.036971405273357655 -0.1660300623645894 -0.0013928710078339604" rpy="0 0 0"/>
      <mass value="3.0"/>
      <inertia ixx="0.021818" iyy="0.002375" izz="0.021750" ixy="0" ixz="0" iyz="0"/>
    </inertial>
    <visual>
      <origin rpy="0 0 0" xyz="0.17915 0.3499 -0.0001"/>
      <geometry>
        <mesh filename="package://kimm_wheel_legged_robot_description/meshes/left_knee_link.stl" scale="0.001 0.001 0.001"/>
      </geometry>
      <material name="silver"/>
    </visual>
    <collision>
      <origin rpy="0 0 0" xyz="0.17915 0.3499 -0.0001"/>
      <geometry>
        <mesh filename="package://kimm_wheel_legged_robot_description/meshes/left_knee_link.stl" scale="0.001 0.001 0.001"/>
      </geometry>
    </collision>
  </link>
  <link name="right_knee_link">
    <inertial>
      <origin xyz="-0.036971405273357655 -0.1660300623645894 -0.0013928710078339604" rpy="0 0 0"/>
      <mass value="3.0"/>
      <inertia ixx="0.021818" iyy="0.002375" izz="0.021750" ixy="0" ixz="0" iyz="0"/>
    </inertial>
    <visual>
      <origin rpy="0 0 0" xyz="-0.17915 0.3499 -0.0001"/>
      <geometry>
        <mesh filename="package://kimm_wheel_legged_robot_description/meshes/right_knee_link.stl" scale="0.001 0.001 0.001"/>
      </geometry>
      <material name="silver"/>
    </visual>
    <collision>
      <origin rpy="0 0 0" xyz="-0.17915 0.3499 -0.0001"/>
      <geometry>
        <mesh filename="package://kimm_wheel_legged_robot_description/meshes/right_knee_link.stl" scale="0.001 0.001 0.001"/>
      </geometry>
    </collision>
  </link>
  <link name="left_long_tendon_connector_link">
    <inertial>
      <origin rpy="0 0 0" xyz="-0.00010680393854881065 -5.000460617443636e-05 0.029010127435682105"/>
      <mass value="0.04250175844733602"/>
      <inertia ixx="3.6e-05" ixy="0.0" ixz="3e-06" iyy="3.6e-05" iyz="-0.0" izz="3e-06"/>
    </inertial>
    <visual>
      <origin rpy="0 0 0" xyz="0.120775 0.4749 -0.0001"/>
      <geometry>
        <mesh filename="package://kimm_wheel_legged_robot_description/meshes/left_long_tendon_connector_link.stl" scale="0.001 0.001 0.001"/>
      </geometry>
      <material name="silver"/>
    </visual>
    <collision>
      <origin rpy="0 0 0" xyz="0.120775 0.4749 -0.0001"/>
      <geometry>
        <mesh filename="package://kimm_wheel_legged_robot_description/meshes/left_long_tendon_connector_link.stl" scale="0.001 0.001 0.001"/>
      </geometry>
    </collision>
  </link>
  <link name="right_long_tendon_connector_link">
    <inertial>
      <origin rpy="0 0 0" xyz="0.00010680393854881065 -5.000460617443636e-05 0.029010127435682105"/>
      <mass value="0.04250175844733602"/>
      <inertia ixx="3.6e-05" ixy="-0.0" ixz="-3e-06" iyy="3.6e-05" iyz="-0.0" izz="3e-06"/>
    </inertial>
    <visual>
      <origin rpy="0 0 0" xyz="-0.120775 0.4749 -0.0001"/>
      <geometry>
        <mesh filename="package://kimm_wheel_legged_robot_description/meshes/right_long_tendon_connector_link.stl" scale="0.001 0.001 0.001"/>
      </geometry>
      <material name="silver"/>
    </visual>
    <collision>
      <origin rpy="0 0 0" xyz="-0.120775 0.4749 -0.0001"/>
      <geometry>
        <mesh filename="package://kimm_wheel_legged_robot_description/meshes/right_long_tendon_connector_link.stl" scale="0.001 0.001 0.001"/>
      </geometry>
    </collision>
  </link>
  <link name="right_short_tendon_connector_link">
    <inertial>
      <origin rpy="0 0 0" xyz="-0.00020680393818853227 -5.0034572285473367e-05 0.029010127448811252"/>
      <mass value="0.04250175844733602"/>
      <inertia ixx="3.6e-05" ixy="-0.0" ixz="3e-06" iyy="3.6e-05" iyz="0.0" izz="3e-06"/>
    </inertial>
    <visual>
      <origin rpy="0 0 0" xyz="-0.163825 0.5749 -0.0001"/>
      <geometry>
        <mesh filename="package://kimm_wheel_legged_robot_description/meshes/right_short_tendon_connector_link.stl" scale="0.001 0.001 0.001"/>
      </geometry>
      <material name="silver"/>
    </visual>
    <collision>
      <origin rpy="0 0 0" xyz="-0.163825 0.5749 -0.0001"/>
      <geometry>
        <mesh filename="package://kimm_wheel_legged_robot_description/meshes/right_short_tendon_connector_link.stl" scale="0.001 0.001 0.001"/>
      </geometry>
    </collision>
  </link>
  <link name="left_short_tendon_connector_link">
    <inertial>
      <origin rpy="0 0 0" xyz="0.00020680393818853227 -5.0034572285473367e-05 0.029010127448811252"/>
      <mass value="0.04250175844733602"/>
      <inertia ixx="3.6e-05" ixy="0.0" ixz="-3e-06" iyy="3.6e-05" iyz="0.0" izz="3e-06"/>
    </inertial>
    <visual>
      <origin rpy="0 0 0" xyz="0.163825 0.5749 -0.0001"/>
      <geometry>
        <mesh filename="package://kimm_wheel_legged_robot_description/meshes/left_short_tendon_connector_link.stl" scale="0.001 0.001 0.001"/>
      </geometry>
      <material name="silver"/>
    </visual>
    <collision>
      <origin rpy="0 0 0" xyz="0.163825 0.5749 -0.0001"/>
      <geometry>
        <mesh filename="package://kimm_wheel_legged_robot_description/meshes/left_short_tendon_connector_link.stl" scale="0.001 0.001 0.001"/>
      </geometry>
    </collision>
  </link>
  <!-- <link name="left_long_tendon_link">
    <inertial>
      <origin rpy="0 0 0" xyz="0.000845101234486112 -0.1074953852625069 0.005010650318331443"/>
      <mass value="0.08788014524255652"/>
      <inertia ixx="0.000509" ixy="-0.0" ixz="-0.0" iyy="4e-06" iyz="0.0" izz="0.000506"/>
    </inertial>
    <visual>
      <origin rpy="0 0 0" xyz="0.125225 0.47495 -0.06005"/>
      <geometry>
        <mesh filename="package://kimm_wheel_legged_robot_description/meshes/left_long_tendon_link.stl" scale="0.001 0.001 0.001"/>
      </geometry>
      <material name="silver"/>
    </visual>
    <collision>
      <origin rpy="0 0 0" xyz="0.125225 0.47495 -0.06005"/>
      <geometry>
        <mesh filename="package://kimm_wheel_legged_robot_description/meshes/left_long_tendon_link.stl" scale="0.001 0.001 0.001"/>
      </geometry>
    </collision>
  </link>
  <link name="right_long_tendon_link">
    <inertial>
      <origin rpy="0 0 0" xyz="-0.0008451012337903491 -0.1074999997162378 0.0049106498049805505"/>
      <mass value="0.08788014524255647"/>
      <inertia ixx="0.000509" ixy="0.0" ixz="0.0" iyy="4e-06" iyz="0.0" izz="0.000506"/>
    </inertial>
    <visual>
      <origin rpy="0 0 0" xyz="-0.125725 0.47495 -0.06005"/>
      <geometry>
        <mesh filename="package://kimm_wheel_legged_robot_description/meshes/right_long_tendon_link.stl" scale="0.001 0.001 0.001"/>
      </geometry>
      <material name="silver"/>
    </visual>
    <collision>
      <origin rpy="0 0 0" xyz="-0.125725 0.47495 -0.06005"/>
      <geometry>
        <mesh filename="package://kimm_wheel_legged_robot_description/meshes/right_long_tendon_link.stl" scale="0.001 0.001 0.001"/>
      </geometry>
    </collision>
  </link>
  <link name="left_short_tendon_link">
    <inertial>
      <origin rpy="0 0 0" xyz="-0.0006571868771749478 -0.057493469589509294 0.003851352991315761"/>
      <mass value="0.05651964524229545"/>
      <inertia ixx="0.000116" ixy="0.0" ixz="0.0" iyy="3e-06" iyz="0.0" izz="0.000113"/>
    </inertial>
    <visual>
      <origin rpy="0 0 0" xyz="0.159275 0.57495 -0.06005"/>
      <geometry>
        <mesh filename="package://kimm_wheel_legged_robot_description/meshes/left_short_tendon_link.stl" scale="0.001 0.001 0.001"/>
      </geometry>
      <material name="silver"/>
    </visual>
    <collision>
      <origin rpy="0 0 0" xyz="0.159275 0.57495 -0.06005"/>
      <geometry>
        <mesh filename="package://kimm_wheel_legged_robot_description/meshes/left_short_tendon_link.stl" scale="0.001 0.001 0.001"/>
      </geometry>
    </collision>
  </link>
  <link name="right_short_tendon_link">
    <inertial>
      <origin rpy="0 0 0" xyz="0.0006571868769024436 -0.057500000104569904 0.003751363801314543"/>
      <mass value="0.056519645242295566"/>
      <inertia ixx="0.000116" ixy="0.0" ixz="-0.0" iyy="3e-06" iyz="-0.0" izz="0.000113"/>
    </inertial>
    <visual>
      <origin rpy="0 0 0" xyz="-0.159775 0.57495 -0.06005"/>
      <geometry>
        <mesh filename="package://kimm_wheel_legged_robot_description/meshes/right_short_tendon_link.stl" scale="0.001 0.001 0.001"/>
      </geometry>
      <material name="silver"/>
    </visual>
    <collision>
      <origin rpy="0 0 0" xyz="-0.159775 0.57495 -0.06005"/>
      <geometry>
        <mesh filename="package://kimm_wheel_legged_robot_description/meshes/right_short_tendon_link.stl" scale="0.001 0.001 0.001"/>
      </geometry>
    </collision>
  </link> -->
  <link name="left_ankle_link">
    <inertial>
      <origin xyz="-0.0011302779004623842 -0.028286432395680183 0.0002742690928544198" rpy="0 0 0"/>
      <mass value="0.3"/>
      <inertia ixx="0.000175" iyy="0.000100" izz="0.000170" ixy="0" ixz="0" iyz="0"/>
    </inertial>
    <visual>
      <origin rpy="0 0 0" xyz="0.142 0.6899 -0.0001"/>
      <geometry>
        <mesh filename="package://kimm_wheel_legged_robot_description/meshes/left_ankle_link.stl" scale="0.001 0.001 0.001"/>
      </geometry>
      <material name="silver"/>
    </visual>
    <collision>
      <origin rpy="0 0 0" xyz="0.142 0.6899 -0.0001"/>
      <geometry>
        <mesh filename="package://kimm_wheel_legged_robot_description/meshes/left_ankle_link.stl" scale="0.001 0.001 0.001"/>
      </geometry>
    </collision>
  </link>
  <link name="right_ankle_link">
    <inertial>
      <origin xyz="0.0011302779004623842 -0.028286432395680183 0.0002742690928544198" rpy="0 0 0"/>
      <mass value="0.3"/>
      <inertia ixx="0.000175" iyy="0.000100" izz="0.000170" ixy="0" ixz="0" iyz="0"/>
    </inertial>
    <visual>
      <origin rpy="0 0 0" xyz="-0.142 0.6899 -0.0001"/>
      <geometry>
        <mesh filename="package://kimm_wheel_legged_robot_description/meshes/right_ankle_link.stl" scale="0.001 0.001 0.001"/>
      </geometry>
      <material name="silver"/>
    </visual>
    <collision>
      <origin rpy="0 0 0" xyz="-0.142 0.6899 -0.0001"/>
      <geometry>
        <mesh filename="package://kimm_wheel_legged_robot_description/meshes/right_ankle_link.stl" scale="0.001 0.001 0.001"/>
      </geometry>
    </collision>
  </link>
  <link name="left_foot_link">
    <inertial>
      <origin xyz="0.00030186809290255745 -0.013615460418342384 -0.04357678195278175" rpy="0 0 0"/>
      <mass value="0.6"/>
      <inertia ixx="0.004026" iyy="0.004097" izz="0.000548" ixy="0" ixz="0" iyz="0"/>
    </inertial>
    <visual>
      <origin rpy="0 0 0" xyz="0.143 0.7319 0.0"/>
      <geometry>
        <mesh filename="package://kimm_wheel_legged_robot_description/meshes/left_foot_link.stl" scale="0.001 0.001 0.001"/>
      </geometry>
      <material name="silver"/>
    </visual>
    <collision>
      <origin rpy="0 0 0" xyz="0.142 0.7319 -0.0"/>
      <geometry>
        <mesh filename="package://kimm_wheel_legged_robot_description/meshes/left_foot_link.stl" scale="0.001 0.001 0.001"/>
      </geometry>
    </collision>
  </link>
  <link name="right_foot_link">
    <inertial>
      <origin xyz="-0.00030186809290255745 -0.013615460418342384 -0.04357678195278175" rpy="0 0 0"/>
      <mass value="0.6"/>
      <inertia ixx="0.004026" iyy="0.004097" izz="0.000548" ixy="0" ixz="0" iyz="0"/>
    </inertial>
    <visual>
      <origin rpy="0 0 0" xyz="-0.143 0.7319 0.0"/>
      <geometry>
        <mesh filename="package://kimm_wheel_legged_robot_description/meshes/right_foot_link.stl" scale="0.001 0.001 0.001"/>
      </geometry>
      <material name="silver"/>
    </visual>
    <collision>
      <origin rpy="0 0 0" xyz="-0.143 0.7319 0.0"/>
      <geometry>
        <mesh filename="package://kimm_wheel_legged_robot_description/meshes/right_foot_link.stl" scale="0.001 0.001 0.001"/>
      </geometry>
    </collision>
  </link>
  <link name="left_foot_wheel_L">
    <inertial>
      <origin xyz="-0.0027500000004113956 -5.023919830760004e-05 -0.0002499336757649795" rpy="0 0 0"/>
      <mass value="0.15"/>
      <inertia ixx="0.000045" iyy="0.000025" izz="0.000025" ixy="0" ixz="0" iyz="0"/>
    </inertial>
    <visual>
      <origin rpy="0 0 0" xyz="0.19675 0.7328 0.154475"/>
      <geometry>
        <mesh filename="package://kimm_wheel_legged_robot_description/meshes/left_foot_wheel_L.stl" scale="0.001 0.001 0.001"/>
      </geometry>
      <material name="silver"/>
    </visual>
    <collision>
      <origin rpy="0 0 0" xyz="0.19675 0.7328 0.154475"/>
      <geometry>
        <mesh filename="package://kimm_wheel_legged_robot_description/meshes/left_foot_wheel_L.stl" scale="0.001 0.001 0.001"/>
      </geometry>
      <surface>
        <friction>
          <ode>
            <mu>1.0</mu>
            <mu2>1.0</mu2>
          </ode>
        </friction>
      </surface>
    </collision>
  </link>
  <link name="right_foot_wheel_R">
    <inertial>
      <origin xyz="0.0027500000004113956 -5.023919830760004e-05 -0.0002499336757649795" rpy="0 0 0"/>
      <mass value="0.15"/>
      <inertia ixx="0.000045" iyy="0.000025" izz="0.000025" ixy="0" ixz="0" iyz="0"/>
    </inertial>
    <visual>
      <origin rpy="0 0 0" xyz="-0.19675 0.7328 0.154475"/>
      <geometry>
        <mesh filename="package://kimm_wheel_legged_robot_description/meshes/right_foot_wheel_R.stl" scale="0.001 0.001 0.001"/>
      </geometry>
      <material name="silver"/>
    </visual>
    <collision>
      <origin rpy="0 0 0" xyz="-0.19675 0.7328 0.154475"/>
      <geometry>
        <mesh filename="package://kimm_wheel_legged_robot_description/meshes/right_foot_wheel_R.stl" scale="0.001 0.001 0.001"/>
      </geometry>
      <surface>
        <friction>
          <ode>
            <mu>1.0</mu>
            <mu2>1.0</mu2>
          </ode>
        </friction>
      </surface>
    </collision>
  </link>
  <link name="left_foot_wheel_R">
    <inertial>
      <origin xyz="0.0022499999995878595 -5.023919831903534e-05 -0.0002499336758523818" rpy="0 0 0"/>
      <mass value="0.15"/>
      <inertia ixx="0.000045" iyy="0.000025" izz="0.000025" ixy="0" ixz="0" iyz="0"/>
    </inertial>
    <visual>
      <origin rpy="0 0 0" xyz="0.08725 0.7328 0.154475"/>
      <geometry>
        <mesh filename="package://kimm_wheel_legged_robot_description/meshes/left_foot_wheel_R.stl" scale="0.001 0.001 0.001"/>
      </geometry>
      <material name="silver"/>
    </visual>
    <collision>
      <origin rpy="0 0 0" xyz="0.08725 0.7328 0.154475"/>
      <geometry>
        <mesh filename="package://kimm_wheel_legged_robot_description/meshes/left_foot_wheel_R.stl" scale="0.001 0.001 0.001"/>
      </geometry>
      <surface>
        <friction>
          <ode>
            <mu>1.0</mu>
            <mu2>1.0</mu2>
          </ode>
        </friction>
      </surface>
    </collision>
  </link>
  <link name="right_foot_wheel_L">
    <inertial>
      <origin xyz="-0.0022499999995878595 -5.023919831903534e-05 -0.0002499336758523818" rpy="0 0 0"/>
      <mass value="0.15"/>
      <inertia ixx="0.000045" iyy="0.000025" izz="0.000025" ixy="0" ixz="0" iyz="0"/>
    </inertial>
    <visual>
      <origin rpy="0 0 0" xyz="-0.08725 0.7328 0.154475"/>
      <geometry>
        <mesh filename="package://kimm_wheel_legged_robot_description/meshes/right_foot_wheel_L.stl" scale="0.001 0.001 0.001"/>
      </geometry>
      <material name="silver"/>
    </visual>
    <collision>
      <origin rpy="0 0 0" xyz="-0.08725 0.7328 0.154475"/>
      <geometry>
        <mesh filename="package://kimm_wheel_legged_robot_description/meshes/right_foot_wheel_L.stl" scale="0.001 0.001 0.001"/>
      </geometry>
    </collision>
  </link>
  <!-- Joints -->
  <joint name="left_pelvis_joint" type="fixed">
    <origin rpy="0 0 0" xyz="-0.0093 0.0 0.0"/>
    <parent link="pelvis"/>
    <child link="left_hip_roll_link"/>
  </joint>
  <joint name="right_pelvis_joint" type="fixed">
    <origin rpy="0 0 0" xyz="0.0093 0.0 0.0"/>
    <parent link="pelvis"/>
    <child link="right_hip_roll_link"/>
  </joint>
  <joint name="torso_joint" type="revolute">
    <origin rpy="0 0 0" xyz="0.0 0.0862 0.0"/>
    <parent link="pelvis"/>
    <child link="torso_link"/>
    <axis xyz="-0.0 -1.0 0.0"/>
    <limit effort="120" lower="-3.141593" upper="3.141593" velocity="5.02"/>
  </joint>
  <joint name="left_hip_roll_joint" type="fixed">
    <origin rpy="0 0 0" xyz="-0.05395 -0.0 0.0"/>
    <parent link="left_hip_roll_link"/>
    <child link="left_hip_yaw_link"/>
    <axis xyz="-1.0 0.0 0.0"/>
    <limit effort="120" lower="-1.919862" upper="1.919862" velocity="5.02"/>
  </joint>
  <joint name="right_hip_roll_joint" type="fixed">
    <origin rpy="0 0 0" xyz="0.05395 0.0 -0.0"/>
    <parent link="right_hip_roll_link"/>
    <child link="right_hip_yaw_link"/>
    <axis xyz="1.0 -0.0 -0.0"/>
    <limit effort="120" lower="-1.919862" upper="1.919862" velocity="5.02"/>
  </joint>
  <joint name="left_hip_yaw_joint" type="fixed">
    <origin rpy="0 0 0" xyz="-0.07915 0.0 -0.03875"/>
    <parent link="left_hip_yaw_link"/>
    <child link="left_hip_pitch_link"/>
    <axis xyz="0.0 -0.0 -1.0"/>
    <limit effort="120" lower="-0.261799" upper="1.570796" velocity="5.02"/>
  </joint>
  <joint name="right_hip_yaw_joint" type="fixed">
    <origin rpy="0 0 0" xyz="0.07915 0.0 -0.03875"/>
    <parent link="right_hip_yaw_link"/>
    <child link="right_hip_pitch_link"/>
    <axis xyz="0.0 0.0 1.0"/>
    <limit effort="120" lower="-0.261799" upper="1.570796" velocity="5.02"/>
  </joint>
  <joint name="left_hip_pitch_joint" type="fixed">
    <origin rpy="0 0 0" xyz="0.0 -0.11825 0.03885"/>
    <parent link="left_hip_pitch_link"/>
    <child link="left_thigh_wheel_link"/>
    <axis xyz="-0.0 -1.0 -0.0"/>
    <limit effort="120" lower="-1.570796" upper="1.570796" velocity="5.02"/>
  </joint>
  <joint name="right_hip_pitch_joint" type="fixed">
    <origin rpy="0 0 0" xyz="0.0 -0.11825 0.03885"/>
    <parent link="right_hip_pitch_link"/>
    <child link="right_thigh_wheel_link"/>
    <axis xyz="0.0 1.0 0.0"/>
    <limit effort="120" lower="-1.570796" upper="1.570796" velocity="5.02"/>
  </joint>
  <joint name="left_wheel_joint" type="continuous">
    <origin rpy="0 0 0" xyz="-0.0635 -0.23165 0.0"/>
    <parent link="left_thigh_wheel_link"/>
    <child link="left_wheel"/>
    <axis xyz="-1.0 -0.0 -0.0"/>
    <limit effort="120" velocity="5.02"/>
  </joint>
  <joint name="right_wheel_joint" type="continuous">
    <origin rpy="0 0 0" xyz="0.0635 -0.23165 0.0"/>
    <parent link="right_thigh_wheel_link"/>
    <child link="right_wheel"/>
    <axis xyz="-1.0 -0.0 -0.0"/>
    <limit effort="120" velocity="5.02"/>
  </joint>
  <joint name="left_knee_joint" type="revolute">
    <origin rpy="0.0 0 0" xyz="-0.03925 -0.23165 0.0"/>
    <parent link="left_thigh_wheel_link"/>
    <child link="left_knee_link"/>
    <axis xyz="-1.0 0.0 0.0"/>
    <limit effort="120" lower="-0.1" upper="2.1" velocity="5.02"/>
  </joint>
  <joint name="right_knee_joint" type="revolute">
    <origin rpy="0.0 0 0" xyz="0.03675 -0.23165 0.0"/>
    <parent link="right_thigh_wheel_link"/>
    <child link="right_knee_link"/>
    <axis xyz="1.0 0.0 -0.0"/>
    <limit effort="120" lower="-2.1" upper="0.1" velocity="5.02"/>
  </joint>
  <joint name="left_ankle_pitch_joint" type="revolute">
    <origin rpy="0 0 0" xyz="0.03965 -0.34 0.0"/>
    <parent link="left_knee_link"/>
    <child link="left_ankle_link"/>
    <axis xyz="1.0 -0.0 -0.0"/>
    <limit effort="24.8" lower="-0.523598" upper="0.523598" velocity="10.8"/>
  </joint>
  <joint name="right_ankle_pitch_joint" type="revolute">
    <origin rpy="0 0 0" xyz="-0.03715 -0.34 0.0"/>
    <parent link="right_knee_link"/>
    <child link="right_ankle_link"/>
    <axis xyz="1.0 0.0 0.0"/>
    <limit effort="24.8" lower="-0.523598" upper="0.523598" velocity="10.8"/>
  </joint>
  <joint name="left_ankle_roll_joint" type="revolute">
    <origin rpy="0 0 0" xyz="0.0 -0.042 -0.0001"/>
    <parent link="left_ankle_link"/>
    <child link="left_foot_link"/>
    <axis xyz="-0.0 -2e-06 -1.0"/>
    <limit effort="24.8" lower="-0.523598" upper="0.523598" velocity="10.8"/>
  </joint>
  <joint name="right_ankle_roll_joint" type="revolute">
    <origin rpy="0 0 0" xyz="0.001 -0.042 -0.0001"/>
    <parent link="right_ankle_link"/>
    <child link="right_foot_link"/>
    <axis xyz="0.0 0.0 1.0"/>
    <limit effort="24.8" lower="-0.523598" upper="0.523598" velocity="10.8"/>
  </joint>
  <joint name="left_foot_wheel_L_joint" type="continuous">
    <origin rpy="0 0 0" xyz="-0.05475 -0.0009 -0.154475"/>
    <parent link="left_foot_link"/>
    <child link="left_foot_wheel_L"/>
    <axis xyz="1.0 -0.0 -0.0"/>
  </joint>
  <joint name="right_foot_wheel_R_joint" type="continuous">
    <origin rpy="0 0 0" xyz="0.05475 -0.0009 -0.154475"/>
    <parent link="right_foot_link"/>
    <child link="right_foot_wheel_R"/>
    <axis xyz="-1.0 0.0 -0.0"/>
  </joint>
  <joint name="left_foot_wheel_R_joint" type="continuous">
    <origin rpy="0 0 0" xyz="0.05475 -0.0009 -0.154475"/>
    <parent link="left_foot_link"/>
    <child link="left_foot_wheel_R"/>
    <axis xyz="-1.0 0.0 0.0"/>
  </joint>
  <joint name="right_foot_wheel_L_joint" type="continuous">
    <origin rpy="0 0 0" xyz="-0.05475 -0.0009 -0.154475"/>
    <parent link="right_foot_link"/>
    <child link="right_foot_wheel_L"/>
    <axis xyz="1.0 -0.0 0.0"/>
  </joint>
  <joint name="left_long_tendon_connector_joint" type="fixed">
    <origin rpy="0 0 0" xyz="0.060875 -0.125 0.0"/>
    <parent link="left_knee_link"/>
    <child link="left_long_tendon_connector_link"/>
    <axis xyz="1.0 -0.0 -0.0"/>
    <limit effort="24.8" lower="-0.523599" upper="0.523599" velocity="10.8"/>
  </joint>
  <joint name="right_long_tendon_connector_joint" type="fixed">
    <origin rpy="0 0 0" xyz="-0.058375 -0.125 0.0"/>
    <parent link="right_knee_link"/>
    <child link="right_long_tendon_connector_link"/>
    <axis xyz="-1.0 -0.0 0.0"/>
    <limit effort="24.8" lower="-0.523599" upper="0.523599" velocity="10.8"/>
  </joint>
  <joint name="left_short_tendon_connector_joint" type="fixed">
    <origin rpy="0 0 0" xyz="0.017825 -0.225 0.0"/>
    <parent link="left_knee_link"/>
    <child link="left_short_tendon_connector_link"/>
    <axis xyz="-1.0 -0.0 0.0"/>
    <limit effort="24.8" lower="-0.523599" upper="0.523599" velocity="10.8"/>
  </joint>
  <joint name="right_short_tendon_connector_joint" type="fixed">
    <origin rpy="0 0 0" xyz="-0.015325 -0.225 0.0"/>
    <parent link="right_knee_link"/>
    <child link="right_short_tendon_connector_link"/>
    <axis xyz="1.0 0.0 -0.0"/>
    <limit effort="24.8" lower="-0.523599" upper="0.523599" velocity="10.8"/>
  </joint>
  <!-- <joint name="left_long_tendon_upper_joint" type="continuous">
    <origin rpy="0 0 0" xyz="-0.00445 -5e-05 0.05995"/>
    <parent link="left_long_tendon_connector_link"/>
    <child link="left_long_tendon_link"/>
    <axis xyz="1.0 0.0 0.0"/>
  </joint>
  <joint name="right_long_tendon_upper_joint" type="continuous">
    <origin rpy="0 0 0" xyz="0.00495 -5e-05 0.05995"/>
    <parent link="right_long_tendon_connector_link"/>
    <child link="right_long_tendon_link"/>
    <axis xyz="1.0 0.0 -0.0"/>
  </joint>
  <joint name="left_short_tendon_upper_joint" type="continuous">
    <origin rpy="0 0 0" xyz="0.00455 -5e-05 0.05995"/>
    <parent link="left_short_tendon_connector_link"/>
    <child link="left_short_tendon_link"/>
    <axis xyz="1.0 -0.0 -0.0"/>
  </joint>
  <joint name="right_short_tendon_upper_joint" type="continuous">
    <origin rpy="0 0 0" xyz="-0.00405 -5e-05 0.05995"/>
    <parent link="right_short_tendon_connector_link"/>
    <child link="right_short_tendon_link"/>
    <axis xyz="1.0 0.0 -0.0"/>
  </joint> -->
</robot>